Workbook

Sheet Customer Names
A1: =PROPER("Customer ID") -> Customer Id | B1: Title | C1: First Name | D1: Last Name
A2: Id1 | B2: Hawks, Ms. Kelly | C2: =LEFT(B2,FIND(" ",B2)-2) -> Hawks | D2: =RIGHT(B2,LEN(B2)-FIND(" ",B2)) -> Kelly
A3: Id2 | B3: Lehner, Mr. Matthew D | C3: =LEFT(B3,FIND(" ",B3)-2) -> Lehner | D3: =RIGHT(B3,LEN(B3)-FIND(" ",B3)) -> Matthew D
A4: Id3 | B4: Lu, Mr. Phil | C4: =LEFT(B4,FIND(" ",B4)-2) -> Lu | D4: =RIGHT(B4,LEN(B4)-FIND(" ",B4)) -> Phil
A5: Id4 | B5: Osborne, Ms. Kelsey | C5: =LEFT(B5,FIND(" ",B5)-2) -> Osborne | D5: =RIGHT(B5,LEN(B5)-FIND(" ",B5)) -> Kelsey
A6: Id5 | B6: Kadala, Ms. Kristyn | C6: =LEFT(B6,FIND(" ",B6)-2) -> Kadala | D6: =RIGHT(B6,LEN(B6)-FIND(" ",B6)) -> Kristyn
A7: Id6 | B7: Baker, Mr. Russell B. | C7: =LEFT(B7,FIND(" ",B7)-2) -> Baker | D7: =RIGHT(B7,LEN(B7)-FIND(" ",B7)) -> Russell B.
A8: Id7 | B8: Macpherson, Mr. Scott | C8: =LEFT(B8,FIND(" ",B8)-2) -> Macpherson | D8: =RIGHT(B8,LEN(B8)-FIND(" ",B8)) -> Scott
A9: Id8 | B9: Hallman, Mr. Stephen | C9: =LEFT(B9,FIND(" ",B9)-2) -> Hallman | D9: =RIGHT(B9,LEN(B9)-FIND(" ",B9)) -> Stephen
A10: Id9 | B10: Moran, Mr. Patrick R. | C10: =LEFT(B10,FIND(" ",B10)-2) -> Moran | D10: =RIGHT(B10,LEN(B10)-FIND(" ",B10)) -> Patrick R.
A11: Id10 | B11: Benner, Ms. Brooke N. | C11: =LEFT(B11,FIND(" ",B11)-2) -> Benner | D11: =RIGHT(B11,LEN(B11)-FIND(" ",B11)) -> Brooke N.
A12: Id11 | B12: Fierro Vargas, Ms. Paola Andrea | C12: =LEFT(B12,FIND(" ",B12)-2) -> Fierr | D12: =RIGHT(B12,LEN(B12)-FIND(" ",B12)) -> Paola Andrea
A13: Id12 | B13: Franz, Mr. David | C13: =LEFT(B13,FIND(" ",B13)-2) -> Franz | D13: =RIGHT(B13,LEN(B13)-FIND(" ",B13)) -> David
... A2336: Id2335 | B2336: German, Mr. Aaron K | C2336: =LEFT(B2336,FIND(" ",B2336)-2) -> German | D2336: =RIGHT(B2336,LEN(B2336)-FIND(" ",B2336)) -> Aaron K

Sheet Medical Examinations
A1: Customer Id | B1: BMI | C1: HBA1C | D1: Heart Issues | E1: Any Transplants | F1: Cancer history | G1: NumberOfMajorSurgeries | H1: smoker | I1: SMOKER | J1: NO.OF.MAJOR SURGERIES | K1: WEIGHT STATUS
A2: Id1 | B2: 47.41 | C2: 7.47 | D2: No | E2: No | F2: No | G2: No major surgery | H2: Yes | I2: =IF(H2="?",$H$2,H2) -> Yes | J2: =IF(G2="No major surgery",0,G2) -> 0 | K2: =IF(B2<18.5,"UNDERWEIGHT",IF(B2<25,"NORMAL WEIGHT",IF(B2<29.9,"OVERWEIGHT","OBESITY"))) -> OBESITY | M2: NO. OF "?' IN CUSTOMER Id COLUMN | N2: COUNTIF | O2: =COUNTIF(A2:A2336,"?") -> 0
A3: Id2 | B3: 30.36 | C3: 5.77 | D3: No | E3: No | F3: No | G3: No major surgery | H3: Yes | I3: =IF(H3="?",$H$2,H3) -> Yes | J3: =IF(G3="No major surgery",0,G3) -> 0 | K3: =IF(B3<18.5,"UNDERWEIGHT",IF(B3<25,"NORMAL WEIGHT",IF(B3<29.9,"OVERWEIGHT","OBESITY"))) -> OBESITY | M3: NO.OF "?" IN BMI COLUMN | N3: COUNTIF | O3: =COUNTIF(B2:B2336,"?") -> 0
A4: Id3 | B4: 34.485 | C4: 11.87 | D4: Yes | E4: No | F4: No | G4: 2 | H4: Yes | I4: =IF(H4="?",$H$2,H4) -> Yes | J4: =IF(G4="No major surgery",0,G4) -> 2 | K4: =IF(B4<18.5,"UNDERWEIGHT",IF(B4<25,"NORMAL WEIGHT",IF(B4<29.9,"OVERWEIGHT","OBESITY"))) -> OBESITY | M4: NO.OF "?" IN HBA1C COLUMN | N4: COUNTIF | O4: =COUNTIF(C2:C2336,"?") -> 0
A5: Id4 | B5: 38.095 | C5: 6.05 | D5: No | E5: No | F5: No | G5: No major surgery | H5: Yes | I5: =IF(H5="?",$H$2,H5) -> Yes | J5: =IF(G5="No major surgery",0,G5) -> 0 | K5: =IF(B5<18.5,"UNDERWEIGHT",IF(B5<25,"NORMAL WEIGHT",IF(B5<29.9,"OVERWEIGHT","OBESITY"))) -> OBESITY | M5: NO.OF "?" IN HEART ISSUE COLUMN | N5: COUNTIF | O5: =COUNTIF(D2:D2336,"?") -> 0
A6: Id5 | B6: 35.53 | C6: 5.45 | D6: No | E6: No | F6: No | G6: No major surgery | H6: Yes | I6: =IF(H6="?",$H$2,H6) -> Yes | J6: =IF(G6="No major surgery",0,G6) -> 0 | K6: =IF(B6<18.5,"UNDERWEIGHT",IF(B6<25,"NORMAL WEIGHT",IF(B6<29.9,"OVERWEIGHT","OBESITY"))) -> OBESITY | M6: NO.OF "?" IN ANY TRANSPLANT COLUMN | N6: COUNTIF | O6: =COUNTIF(E2:E2336,"?") -> 0
A7: Id6 | B7: 32.8 | C7: 6.59 | D7: No | E7: No | F7: No | G7: No major surgery | H7: Yes | I7: =IF(H7="?",$H$2,H7) -> Yes | J7: =IF(G7="No major surgery",0,G7) -> 0 | K7: =IF(B7<18.5,"UNDERWEIGHT",IF(B7<25,"NORMAL WEIGHT",IF(B7<29.9,"OVERWEIGHT","OBESITY"))) -> OBESITY | M7: NO.OF "?" IN CANCER HISTORY COLUMN | N7: COUNTIF | O7: =COUNTIF(F2:F2336,"?") -> 0
A8: Id7 | B8: 36.4 | C8: 6.07 | D8: No | E8: No | F8: No | G8: No major surgery | H8: Yes | I8: =IF(H8="?",$H$2,H8) -> Yes | J8: =IF(G8="No major surgery",0,G8) -> 0 | K8: =IF(B8<18.5,"UNDERWEIGHT",IF(B8<25,"NORMAL WEIGHT",IF(B8<29.9,"OVERWEIGHT","OBESITY"))) -> OBESITY | M8: NO.OF "?" IN MAJOR SURGERIES COLUMN | N8: COUNTIF | O8: =COUNTIF(G2:G2336,"?") -> 0
A9: Id8 | B9: 36.96 | C9: 7.93 | D9: No | E9: No | F9: No | G9: 3 | H9: Yes | I9: =IF(H9="?",$H$2,H9) -> Yes | J9: =IF(G9="No major surgery",0,G9) -> 3 | K9: =IF(B9<18.5,"UNDERWEIGHT",IF(B9<25,"NORMAL WEIGHT",IF(B9<29.9,"OVERWEIGHT","OBESITY"))) -> OBESITY | M9: NO.OF "?" IN SMOKER TIERCOLUMN | N9: COUNTIF | O9: =COUNTIF(H2:H2336,"?") -> 2
A10: Id9 | B10: 41.14 | C10: 9.58 | D10: Yes | E10: No | F10: Yes | G10: 1 | H10: Yes | I10: =IF(H10="?",$H$2,H10) -> Yes | J10: =IF(G10="No major surgery",0,G10) -> 1 | K10: =IF(B10<18.5,"UNDERWEIGHT",IF(B10<25,"NORMAL WEIGHT",IF(B10<29.9,"OVERWEIGHT","OBESITY"))) -> OBESITY | N10: TOTAL | O10: =SUM(O2:O9) -> 2
A11: Id10 | B11: 38.06 | C11: 10.79 | D11: No | E11: No | F11: No | G11: No major surgery | H11: Yes | I11: =IF(H11="?",$H$2,H11) -> Yes | J11: =IF(G11="No major surgery",0,G11) -> 0 | K11: =IF(B11<18.5,"UNDERWEIGHT",IF(B11<25,"NORMAL WEIGHT",IF(B11<29.9,"OVERWEIGHT","OBESITY"))) -> OBESITY
A12: Id11 | B12: 37.7 | C12: 5.96 | D12: Yes | E12: No | F12: No | G12: 2 | H12: Yes | I12: =IF(H12="?",$H$2,H12) -> Yes | J12: =IF(G12="No major surgery",0,G12) -> 2 | K12: =IF(B12<18.5,"UNDERWEIGHT",IF(B12<25,"NORMAL WEIGHT",IF(B12<29.9,"OVERWEIGHT","OBESITY"))) -> OBESITY
A13: Id12 | B13: 42.13 | C13: 11.9 | D13: No | E13: No | F13: No | G13: No major surgery | H13: Yes | I13: =IF(H13="?",$H$2,H13) -> Yes | J13: =IF(G13="No major surgery",0,G13) -> 0 | K13: =IF(B13<18.5,"UNDERWEIGHT",IF(B13<25,"NORMAL WEIGHT",IF(B13<29.9,"OVERWEIGHT","OBESITY"))) -> OBESITY
A14: Id13 | B14: 40.92 | C14: 8.41 | D14: No | E14: No | F14: No | G14: No major surgery | H14: Yes | I14: =IF(H14="?",$H$2,H14) -> Yes | J14: =IF(G14="No major surgery",0,G14) -> 0 | K14: =IF(B14<18.5,"UNDERWEIGHT",IF(B14<25,"NORMAL WEIGHT",IF(B14<29.9,"OVERWEIGHT","OBESITY"))) -> OBESITY | M14: NO. OF SMOKER IS "Yes" | N14: COUNTIF | O14: =COUNTIF(I2:I2336,"Yes") -> 490
A15: Id14 | B15: 40.565 | C15: 7.02 | D15: No | E15: No | F15: No | G15: No major surgery | H15: Yes | I15: =IF(H15="?",$H$2,H15) -> Yes | J15: =IF(G15="No major surgery",0,G15) -> 0 | K15: =IF(B15<18.5,"UNDERWEIGHT",IF(B15<25,"NORMAL WEIGHT",IF(B15<29.9,"OVERWEIGHT","OBESITY"))) -> OBESITY | M15: NO. OF SMOKER IS" NO" | N15: COUNTIF | O15: =COUNTIF(I2:I2366,"no") -> 1845
A16: Id15 | B16: 36.385 | C16: 7.59 | D16: Yes | E16: No | F16: No | G16: 2 | H16: Yes | I16: =IF(H16="?",$H$2,H16) -> Yes | J16: =IF(G16="No major surgery",0,G16) -> 2 | K16: =IF(B16<18.5,"UNDERWEIGHT",IF(B16<25,"NORMAL WEIGHT",IF(B16<29.9,"OVERWEIGHT","OBESITY"))) -> OBESITY
A17: Id16 | B17: 39.9 | C17: 11.32 | D17: No | E17: No | F17: No | G17: No major surgery | H17: Yes | I17: =IF(H17="?",$H$2,H17) -> Yes | J17: =IF(G17="No major surgery",0,G17) -> 0 | K17: =IF(B17<18.5,"UNDERWEIGHT",IF(B17<25,"NORMAL WEIGHT",IF(B17<29.9,"OVERWEIGHT","OBESITY"))) -> OBESITY
A18: Id17 | B18: 33.8 | C18: 7.67 | D18: No | E18: No | F18: No | G18: 3 | H18: Yes | I18: =IF(H18="?",$H$2,H18) -> Yes | J18: =IF(G18="No major surgery",0,G18) -> 3 | K18: =IF(B18<18.5,"UNDERWEIGHT",IF(B18<25,"NORMAL WEIGHT",IF(B18<29.9,"OVERWEIGHT","OBESITY"))) -> OBESITY
A19: Id18 | B19: 36.765 | C19: 7.29 | D19: Yes | E19: No | F19: Yes | G19: 1 | H19: Yes | I19: =IF(H19="?",$H$2,H19) -> Yes | J19: =IF(G19="No major surgery",0,G19) -> 1 | K19: =IF(B19<18.5,"UNDERWEIGHT",IF(B19<25,"NORMAL WEIGHT",IF(B19<29.9,"OVERWEIGHT","OBESITY"))) -> OBESITY
A20: Id19 | B20: 36.955 | C20: 4.72 | D20: Yes | E20: No | F20: No | G20: 1 | H20: Yes | I20: =IF(H20="?",$H$2,H20) -> Yes | J20: =IF(G20="No major surgery",0,G20) -> 1 | K20: =IF(B20<18.5,"UNDERWEIGHT",IF(B20<25,"NORMAL WEIGHT",IF(B20<29.9,"OVERWEIGHT","OBESITY"))) -> OBESITY
A21: Id20 | B21: 42.9 | C21: 11.41 | D21: No | E21: No | F21: No | G21: No major surgery | H21: Yes | I21: =IF(H21="?",$H$2,H21) -> Yes | J21: =IF(G21="No major surgery",0,G21) -> 0 | K21: =IF(B21<18.5,"UNDERWEIGHT",IF(B21<25,"NORMAL WEIGHT",IF(B21<29.9,"OVERWEIGHT","OBESITY"))) -> OBESITY
A22: Id21 | B22: 36.3 | C22: 11.5 | D22: Yes | E22: No | F22: No | G22: 2 | H22: Yes | I22: =IF(H22="?",$H$2,H22) -> Yes | J22: =IF(G22="No major surgery",0,G22) -> 2 | K22: =IF(B22<18.5,"UNDERWEIGHT",IF(B22<25,"NORMAL WEIGHT",IF(B22<29.9,"OVERWEIGHT","OBESITY"))) -> OBESITY
A23: Id22 | B23: 32.2 | C23: 6.22 | D23: Yes | E23: No | F23: No | G23: 2 | H23: Yes | I23: =IF(H23="?",$H$2,H23) -> Yes | J23: =IF(G23="No major surgery",0,G23) -> 2 | K23: =IF(B23<18.5,"UNDERWEIGHT",IF(B23<25,"NORMAL WEIGHT",IF(B23<29.9,"OVERWEIGHT","OBESITY"))) -> OBESITY
A24: Id23 | B24: 31.3 | C24: 11.38 | D24: No | E24: No | F24: No | G24: 3 | H24: Yes | I24: =IF(H24="?",$H$2,H24) -> Yes | J24: =IF(G24="No major surgery",0,G24) -> 3 | K24: =IF(B24<18.5,"UNDERWEIGHT",IF(B24<25,"NORMAL WEIGHT",IF(B24<29.9,"OVERWEIGHT","OBESITY"))) -> OBESITY
A25: Id24 | B25: 41.8 | C25: 7.89 | D25: Yes | E25: No | F25: No | G25: 2 | H25: Yes | I25: =IF(H25="?",$H$2,H25) -> Yes | J25: =IF(G25="No major surgery",0,G25) -> 2 | K25: =IF(B25<18.5,"UNDERWEIGHT",IF(B25<25,"NORMAL WEIGHT",IF(B25<29.9,"OVERWEIGHT","OBESITY"))) -> OBESITY
A26: Id25 | B26: 35.09 | C26: 4.38 | D26: Yes | E26: No | F26: No | G26: 2 | H26: Yes | I26: =IF(H26="?",$H$2,H26) -> Yes | J26: =IF(G26="No major surgery",0,G26) -> 2 | K26: =IF(B26<18.5,"UNDERWEIGHT",IF(B26<25,"NORMAL WEIGHT",IF(B26<29.9,"OVERWEIGHT","OBESITY"))) -> OBESITY
A27: Id26 | B27: 33.88 | C27: 7.01 | D27: No | E27: No | F27: No | G27: 3 | H27: Yes | I27: =IF(H27="?",$H$2,H27) -> Yes | J27: =IF(G27="No major surgery",0,G27) -> 3 | K27: =IF(B27<18.5,"UNDERWEIGHT",IF(B27<25,"NORMAL WEIGHT",IF(B27<29.9,"OVERWEIGHT","OBESITY"))) -> OBESITY
A28: Id27 | B28: 30.875 | C28: 11.88 | D28: No | E28: No | F28: No | G28: No major surgery | H28: Yes | I28: =IF(H28="?",$H$2,H28) -> Yes | J28: =IF(G28="No major surgery",0,G28) -> 0 | K28: =IF(B28<18.5,"UNDERWEIGHT",IF(B28<25,"NORMAL WEIGHT",IF(B28<29.9,"OVERWEIGHT","OBESITY"))) -> OBESITY
A29: Id28 | B29: 36.86 | C29: 5.19 | D29: Yes | E29: No | F29: Yes | G29: 1 | H29: Yes | I29: =IF(H29="?",$H$2,H29) -> Yes | J29: =IF(G29="No major surgery",0,G29) -> 1 | K29: =IF(B29<18.5,"UNDERWEIGHT",IF(B29<25,"NORMAL WEIGHT",IF(B29<29.9,"OVERWEIGHT","OBESITY"))) -> OBESITY
A30: Id29 | B30: 35.86 | C30: 6.74 | D30: Yes | E30: No | F30: No | G30: 2 | H30: Yes | I30: =IF(H30="?",$H$2,H30) -> Yes | J30: =IF(G30="No major surgery",0,G30) -> 2 | K30: =IF(B30<18.5,"UNDERWEIGHT",IF(B30<25,"NORMAL WEIGHT",IF(B30<29.9,"OVERWEIGHT","OBESITY"))) -> OBESITY
A31: Id30 | B31: 37.05 | C31: 8.44 | D31: No | E31: No | F31: No | G31: No major surgery | H31: Yes | I31: =IF(H31="?",$H$2,H31) -> Yes | J31: =IF(G31="No major surgery",0,G31) -> 0 | K31: =IF(B31<18.5,"UNDERWEIGHT",IF(B31<25,"NORMAL WEIGHT",IF(B31<29.9,"OVERWEIGHT","OBESITY"))) -> OBESITY
A32: Id31 | B32: 43.89 | C32: 8.71 | D32: No | E32: No | F32: No | G32: No major surgery | H32: Yes | I32: =IF(H32="?",$H$2,H32) -> Yes | J32: =IF(G32="No major surgery",0,G32) -> 0 | K32: =IF(B32<18.5,"UNDERWEIGHT",IF(B32<25,"NORMAL WEIGHT",IF(B32<29.9,"OVERWEIGHT","OBESITY"))) -> OBESITY
A33: Id32 | B33: 42.35 | C33: 5.08 | D33: Yes | E33: No | F33: No | G33: No major surgery | H33: Yes | I33: =IF(H33="?",$H$2,H33) -> Yes | J33: =IF(G33="No major surgery",0,G33) -> 0 | K33: =IF(B33<18.5,"UNDERWEIGHT",IF(B33<25,"NORMAL WEIGHT",IF(B33<29.9,"OVERWEIGHT","OBESITY"))) -> OBESITY
A34: Id33 | B34: 31.35 | C34: 6.86 | D34: No | E34: No | F34: No | G34: No major surgery | H34: Yes | I34: =IF(H34="?",$H$2,H34) -> Yes | J34: =IF(G34="No major surgery",0,G34) -> 0 | K34: =IF(B34<18.5,"UNDERWEIGHT",IF(B34<25,"NORMAL WEIGHT",IF(B34<29.9,"OVERWEIGHT","OBESITY"))) -> OBESITY
A35: Id34 | B35: 47.6 | C35: 5.95 | D35: Yes | E35: No | F35: No | G35: No major surgery | H35: Yes | I35: =IF(H35="?",$H$2,H35) -> Yes | J35: =IF(G35="No major surgery",0,G35) -> 0 | K35: =IF(B35<18.5,"UNDERWEIGHT",IF(B35<25,"NORMAL WEIGHT",IF(B35<29.9,"OVERWEIGHT","OBESITY"))) -> OBESITY
A36: Id35 | B36: 46.2 | C36: 6.09 | D36: No | E36: No | F36: Yes | G36: 1 | H36: Yes | I36: =IF(H36="?",$H$2,H36) -> Yes | J36: =IF(G36="No major surgery",0,G36) -> 1 | K36: =IF(B36<18.5,"UNDERWEIGHT",IF(B36<25,"NORMAL WEIGHT",IF(B36<29.9,"OVERWEIGHT","OBESITY"))) -> OBESITY
A37: Id36 | B37: 32.015 | C37: 11.75 | D37: No | E37: No | F37: No | G37: No major surgery | H37: Yes | I37: =IF(H37="?",$H$2,H37) -> Yes | J37: =IF(G37="No major surgery",0,G37) -> 0 | K37: =IF(B37<18.5,"UNDERWEIGHT",IF(B37<25,"NORMAL WEIGHT",IF(B37<29.9,"OVERWEIGHT","OBESITY"))) -> OBESITY
A38: Id37 | B38: 40.565 | C38: 7.37 | D38: No | E38: No | F38: No | G38: No major surgery | H38: Yes | I38: =IF(H38="?",$H$2,H38) -> Yes | J38: =IF(G38="No major surgery",0,G38) -> 0 | K38: =IF(B38<18.5,"UNDERWEIGHT",IF(B38<25,"NORMAL WEIGHT",IF(B38<29.9,"OVERWEIGHT","OBESITY"))) -> OBESITY
A39: Id38 | B39: 32.45 | C39: 11.91 | D39: No | E39: No | F39: No | G39: No major surgery | H39: Yes | I39: =IF(H39="?",$H$2,H39) -> Yes | J39: =IF(G39="No major surgery",0,G39) -> 0 | K39: =IF(B39<18.5,"UNDERWEIGHT",IF(B39<25,"NORMAL WEIGHT",IF(B39<29.9,"OVERWEIGHT","OBESITY"))) -> OBESITY
A40: Id39 | B40: 34.96 | C40: 6.52 | D40: No | E40: No | F40: No | G40: No major surgery | H40: Yes | I40: =IF(H40="?",$H$2,H40) -> Yes | J40: =IF(G40="No major surgery",0,G40) -> 0 | K40: =IF(B40<18.5,"UNDERWEIGHT",IF(B40<25,"NORMAL WEIGHT",IF(B40<29.9,"OVERWEIGHT","OBESITY"))) -> OBESITY
...

Sheet Hospitalisation Details
A1: Customer ID | B1: Year | C1: MONTH | D1: Date | E1: DATE OF BIRTH | F1: Children | G1: Charges | H1: Hospital tier | I1: City tier | J1: State ID | K1: AVERAGE YEAR | L1: HOSPITAL TIER | M1: CITY TIER | N1: STATE ID | O1: Age | P1: DATE OF BIRTH
A2: Id999 | B2: 1969 | C2: Aug | D2: 20 | E2: =DATE(K2, MONTH(1 & C2), D2) -> 25435 | F2: 3 | G2: 11253.42 | H2: tier - 3 | I2: tier - 1 | J2: R1011 | K2: =IF(B2="?",ROUND(AVERAGE($B$2:$B$2344),0),B2) -> 1969 | L2: =IF(H2="?",$H$2,H2) -> tier - 3 | M2: =IF(I2="?",$I$2,I2) -> tier - 1 | N2: =IF(J2="?","UNKNOWN",J2) -> R1011 | O2: =IFERROR(INT(YEARFRAC(E2, DATE(2023,6,8))), "") -> 53 | P2: 25435 | R2: =Q28-B2 -> 43116
A3: Id998 | B3: 1981 | C3: Oct | D3: 2 | E3: =DATE(K3, MONTH(1 & C3), D3) -> 29861 | F3: 1 | G3: 11255.29 | H3: tier - 3 | I3: tier - 1 | J3: R1026 | K3: =IF(B3="?",ROUND(AVERAGE($B$2:$B$2344),0),B3) -> 1981 | L3: =IF(H3="?",$H$2,H3) -> tier - 3 | M3: =IF(I3="?",$I$2,I3) -> tier - 1 | N3: =IF(J3="?","UNKNOWN",J3) -> R1026 | O3: =IFERROR(INT(YEARFRAC(E3, DATE(2023,6,8))), "") -> 41 | P3: 29861 | Q3: NO. OF "?' IN CUSTOMER COLUMN | R3: COUNTIF | S3: =COUNTIF(A2:A2344,"?") -> 6
A4: Id997 | B4: 1969 | C4: Oct | D4: 11 | E4: =DATE(K4, MONTH(1 & C4), D4) -> 25487 | F4: 3 | G4: 11264.54 | H4: tier - 3 | I4: tier - 2 | J4: R1011 | K4: =IF(B4="?",ROUND(AVERAGE($B$2:$B$2344),0),B4) -> 1969 | L4: =IF(H4="?",$H$2,H4) -> tier - 3 | M4: =IF(I4="?",$I$2,I4) -> tier - 2 | N4: =IF(J4="?","UNKNOWN",J4) -> R1011 | O4: =IFERROR(INT(YEARFRAC(E4, DATE(2023,6,8))), "") -> 53 | P4: 25487 | Q4: NO.OF "?" IN YEAR COLUMN | R4: COUNTIF | S4: =COUNTIF(B2:B2344,"?") -> 2
A5: Id996 | B5: 1971 | C5: Dec | D5: 26 | E5: =DATE(K5, MONTH(1 & C5), D5) -> 26293 | F5: 0 | G5: 11265.71 | H5: tier - 3 | I5: tier - 1 | J5: R1025 | K5: =IF(B5="?",ROUND(AVERAGE($B$2:$B$2344),0),B5) -> 1971 | L5: =IF(H5="?",$H$2,H5) -> tier - 3 | M5: =IF(I5="?",$I$2,I5) -> tier - 1 | N5: =IF(J5="?","UNKNOWN",J5) -> R1025 | O5: =IFERROR(INT(YEARFRAC(E5, DATE(2023,6,8))), "") -> 51 | P5: 26293 | Q5: NO.OF "?" IN MONTH COLUMN | R5: COUNTIF | S5: =COUNTIF(C2:C2344,"?") -> 0
A6: Id995 | B6: 2004 | C6: Oct | D6: 4 | E6: =DATE(K6, MONTH(1 & C6), D6) -> 38264 | F6: 1 | G6: 11272.33 | H6: tier - 3 | I6: tier - 2 | J6: R1019 | K6: =IF(B6="?",ROUND(AVERAGE($B$2:$B$2344),0),B6) -> 2004 | L6: =IF(H6="?",$H$2,H6) -> tier - 3 | M6: =IF(I6="?",$I$2,I6) -> tier - 2 | N6: =IF(J6="?","UNKNOWN",J6) -> R1019 | O6: =IFERROR(INT(YEARFRAC(E6, DATE(2023,6,8))), "") -> 18 | P6: 38264 | Q6: NO.OF "?" IN DATE COLUMN | R6: COUNTIF | S6: =COUNTIF(D2:D2344,"?") -> 0
A7: Id994 | B7: 1967 | C7: Jun | D7: 14 | E7: =DATE(K7, MONTH(1 & C7), D7) -> 24637 | F7: 0 | G7: 11286.54 | H7: tier - 3 | I7: tier - 3 | J7: R1024 | K7: =IF(B7="?",ROUND(AVERAGE($B$2:$B$2344),0),B7) -> 1967 | L7: =IF(H7="?",$H$2,H7) -> tier - 3 | M7: =IF(I7="?",$I$2,I7) -> tier - 3 | N7: =IF(J7="?","UNKNOWN",J7) -> R1024 | O7: =IFERROR(INT(YEARFRAC(E7, DATE(2023,6,8))), "") -> 55 | P7: 24637 | Q7: NO.OF "?" IN CHILDREN COLUMN | R7: COUNTIF | S7: =COUNTIF(F2:F2344,"?") -> 0
A8: Id993 | B8: 1970 | C8: Jun | D8: 22 | E8: =DATE(K8, MONTH(1 & C8), D8) -> 25741 | F8: 3 | G8: 11289.11 | H8: tier - 3 | I8: tier - 1 | J8: R1012 | K8: =IF(B8="?",ROUND(AVERAGE($B$2:$B$2344),0),B8) -> 1970 | L8: =IF(H8="?",$H$2,H8) -> tier - 3 | M8: =IF(I8="?",$I$2,I8) -> tier - 1 | N8: =IF(J8="?","UNKNOWN",J8) -> R1012 | O8: =IFERROR(INT(YEARFRAC(E8, DATE(2023,6,8))), "") -> 52 | P8: 25741 | Q8: NO.OF "?" IN CHARGES COLUMN | R8: COUNTIF | S8: =COUNTIF(G2:G2344,"?") -> 0
A9: Id992 | B9: 1988 | C9: Nov | D9: 14 | E9: =DATE(K9, MONTH(1 & C9), D9) -> 32461 | F9: 3 | G9: 11294.57 | H9: tier - 3 | I9: tier - 1 | J9: R1022 | K9: =IF(B9="?",ROUND(AVERAGE($B$2:$B$2344),0),B9) -> 1988 | L9: =IF(H9="?",$H$2,H9) -> tier - 3 | M9: =IF(I9="?",$I$2,I9) -> tier - 1 | N9: =IF(J9="?","UNKNOWN",J9) -> R1022 | O9: =IFERROR(INT(YEARFRAC(E9, DATE(2023,6,8))), "") -> 34 | P9: 32461 | Q9: NO.OF "?" IN HOSPITAL TIER COLUMN | R9: COUNTIF | S9: =COUNTIF(H2:H2344,"?") -> 1
A10: Id991 | B10: 1972 | C10: Sep | D10: 25 | E10: =DATE(K10, MONTH(1 & C10), D10) -> 26567 | F10: 4 | G10: 11299.34 | H10: tier - 3 | I10: tier - 2 | J10: R1011 | K10: =IF(B10="?",ROUND(AVERAGE($B$2:$B$2344),0),B10) -> 1972 | L10: =IF(H10="?",$H$2,H10) -> tier - 3 | M10: =IF(I10="?",$I$2,I10) -> tier - 2 | N10: =IF(J10="?","UNKNOWN",J10) -> R1011 | O10: =IFERROR(INT(YEARFRAC(E10, DATE(2023,6,8))), "") -> 50 | P10: 26567 | Q10: NO.OF "?" IN CITY TIERCOLUMN | R10: COUNTIF | S10: =COUNTIF(I2:I2344,"?") -> 1
A11: Id990 | B11: 1968 | C11: Oct | D11: 6 | E11: =DATE(K11, MONTH(1 & C11), D11) -> 25117 | F11: 1 | G11: 11305.93 | H11: tier - 3 | I11: tier - 1 | J11: R1012 | K11: =IF(B11="?",ROUND(AVERAGE($B$2:$B$2344),0),B11) -> 1968 | L11: =IF(H11="?",$H$2,H11) -> tier - 3 | M11: =IF(I11="?",$I$2,I11) -> tier - 1 | N11: =IF(J11="?","UNKNOWN",J11) -> R1012 | O11: =IFERROR(INT(YEARFRAC(E11, DATE(2023,6,8))), "") -> 54 | P11: 25117 | Q11: NO.OF "?" IN STATE COLUMN | R11: COUNTIF | S11: =COUNTIF(J2:J2344,"?") -> 2
A12: Id99 | B12: 1962 | C12: Sep | D12: 4 | E12: =DATE(K12, MONTH(1 & C12), D12) -> 22893 | F12: 0 | G12: 40309.93 | H12: tier - 1 | I12: tier - 3 | J12: R1011 | K12: =IF(B12="?",ROUND(AVERAGE($B$2:$B$2344),0),B12) -> 1962 | L12: =IF(H12="?",$H$2,H12) -> tier - 1 | M12: =IF(I12="?",$I$2,I12) -> tier - 3 | N12: =IF(J12="?","UNKNOWN",J12) -> R1011 | O12: =IFERROR(INT(YEARFRAC(E12, DATE(2023,6,8))), "") -> 60 | P12: 22893 | R12: TOTAL | S12: =SUM(S3:S11) -> 12
A13: Id989 | B13: 1963 | C13: Nov | D13: 22 | E13: =DATE(K13, MONTH(1 & C13), D13) -> 23337 | F13: 0 | G13: 11312.33 | H13: tier - 3 | I13: tier - 3 | J13: R1012 | K13: =IF(B13="?",ROUND(AVERAGE($B$2:$B$2344),0),B13) -> 1963 | L13: =IF(H13="?",$H$2,H13) -> tier - 3 | M13: =IF(I13="?",$I$2,I13) -> tier - 3 | N13: =IF(J13="?","UNKNOWN",J13) -> R1012 | O13: =IFERROR(INT(YEARFRAC(E13, DATE(2023,6,8))), "") -> 59 | P13: 23337
A14: Id988 | B14: 1995 | C14: Dec | D14: 10 | E14: =DATE(K14, MONTH(1 & C14), D14) -> 35043 | F14: 0 | G14: 11318.57 | H14: tier - 3 | I14: tier - 2 | J14: R1026 | K14: =IF(B14="?",ROUND(AVERAGE($B$2:$B$2344),0),B14) -> 1995 | L14: =IF(H14="?",$H$2,H14) -> tier - 3 | M14: =IF(I14="?",$I$2,I14) -> tier - 2 | N14: =IF(J14="?","UNKNOWN",J14) -> R1026 | O14: =IFERROR(INT(YEARFRAC(E14, DATE(2023,6,8))), "") -> 27 | P14: 35043
A15: Id987 | B15: 1963 | C15: Jul | D15: 11 | E15: =DATE(K15, MONTH(1 & C15), D15) -> 23203 | F15: 0 | G15: 11319.12 | H15: tier - 3 | I15: tier - 1 | J15: R1012 | K15: =IF(B15="?",ROUND(AVERAGE($B$2:$B$2344),0),B15) -> 1963 | L15: =IF(H15="?",$H$2,H15) -> tier - 3 | M15: =IF(I15="?",$I$2,I15) -> tier - 1 | N15: =IF(J15="?","UNKNOWN",J15) -> R1012 | O15: =IFERROR(INT(YEARFRAC(E15, DATE(2023,6,8))), "") -> 59 | P15: 23203
A16: Id986 | B16: 2002 | C16: Sep | D16: 20 | E16: =DATE(K16, MONTH(1 & C16), D16) -> 37519 | F16: 0 | G16: 11321.49 | H16: tier - 3 | I16: tier - 3 | J16: R1012 | K16: =IF(B16="?",ROUND(AVERAGE($B$2:$B$2344),0),B16) -> 2002 | L16: =IF(H16="?",$H$2,H16) -> tier - 3 | M16: =IF(I16="?",$I$2,I16) -> tier - 3 | N16: =IF(J16="?","UNKNOWN",J16) -> R1012 | O16: =IFERROR(INT(YEARFRAC(E16, DATE(2023,6,8))), "") -> 20 | P16: 37519 | Q16: HOSPITAL REPEATED TIER - 1 | R16: COUNTIF | S16: =COUNTIF(L2:L2344,"tier - 1") -> 309
A17: Id985 | B17: 1989 | C17: Aug | D17: 19 | E17: =DATE(K17, MONTH(1 & C17), D17) -> 32739 | F17: 1 | G17: 11326.71 | H17: tier - 3 | I17: tier - 3 | J17: R1013 | K17: =IF(B17="?",ROUND(AVERAGE($B$2:$B$2344),0),B17) -> 1989 | L17: =IF(H17="?",$H$2,H17) -> tier - 3 | M17: =IF(I17="?",$I$2,I17) -> tier - 3 | N17: =IF(J17="?","UNKNOWN",J17) -> R1013 | O17: =IFERROR(INT(YEARFRAC(E17, DATE(2023,6,8))), "") -> 33 | P17: 32739 | Q17: HOSPITAL REPEATED TIER - 2 | R17: COUNTIF | S17: =COUNTIF(L2:L2344,"tier - 2") -> 1339
A18: Id984 | B18: 1968 | C18: Nov | D18: 2 | E18: =DATE(K18, MONTH(1 & C18), D18) -> 25144 | F18: 0 | G18: 11344.32 | H18: tier - 3 | I18: tier - 2 | J18: R1025 | K18: =IF(B18="?",ROUND(AVERAGE($B$2:$B$2344),0),B18) -> 1968 | L18: =IF(H18="?",$H$2,H18) -> tier - 3 | M18: =IF(I18="?",$I$2,I18) -> tier - 2 | N18: =IF(J18="?","UNKNOWN",J18) -> R1025 | O18: =IFERROR(INT(YEARFRAC(E18, DATE(2023,6,8))), "") -> 54 | P18: 25144 | Q18: HOSPITAL REPEATED TIER - 3 | R18: COUNTIF | S18: =COUNTIF(L2:L2344,"tier - 3") -> 695
A19: Id983 | B19: 1964 | C19: Jul | D19: 12 | E19: =DATE(K19, MONTH(1 & C19), D19) -> 23570 | F19: 0 | G19: 11345.52 | H19: tier - 3 | I19: tier - 3 | J19: R1011 | K19: =IF(B19="?",ROUND(AVERAGE($B$2:$B$2344),0),B19) -> 1964 | L19: =IF(H19="?",$H$2,H19) -> tier - 3 | M19: =IF(I19="?",$I$2,I19) -> tier - 3 | N19: =IF(J19="?","UNKNOWN",J19) -> R1011 | O19: =IFERROR(INT(YEARFRAC(E19, DATE(2023,6,8))), "") -> 58 | P19: 23570
A20: Id982 | B20: 1965 | C20: Nov | D20: 29 | E20: =DATE(K20, MONTH(1 & C20), D20) -> 24075 | F20: 0 | G20: 11353.23 | H20: tier - 3 | I20: tier - 1 | J20: R1012 | K20: =IF(B20="?",ROUND(AVERAGE($B$2:$B$2344),0),B20) -> 1965 | L20: =IF(H20="?",$H$2,H20) -> tier - 3 | M20: =IF(I20="?",$I$2,I20) -> tier - 1 | N20: =IF(J20="?","UNKNOWN",J20) -> R1012 | O20: =IFERROR(INT(YEARFRAC(E20, DATE(2023,6,8))), "") -> 57 | P20: 24075
A21: Id981 | B21: 1965 | C21: Sep | D21: 26 | E21: =DATE(K21, MONTH(1 & C21), D21) -> 24011 | F21: 0 | G21: 11356.66 | H21: tier - 3 | I21: tier - 3 | J21: R1012 | K21: =IF(B21="?",ROUND(AVERAGE($B$2:$B$2344),0),B21) -> 1965 | L21: =IF(H21="?",$H$2,H21) -> tier - 3 | M21: =IF(I21="?",$I$2,I21) -> tier - 3 | N21: =IF(J21="?","UNKNOWN",J21) -> R1012 | O21: =IFERROR(INT(YEARFRAC(E21, DATE(2023,6,8))), "") -> 57 | P21: 24011 | Q21: CITY TIER - 1 | R21: COUNTIF | S21: =COUNTIF(M2:M2344,"tier - 1") -> 735
A22: Id980 | B22: 1964 | C22: Jul | D22: 4 | E22: =DATE(K22, MONTH(1 & C22), D22) -> 23562 | F22: 0 | G22: 11362.76 | H22: tier - 3 | I22: tier - 1 | J22: R1011 | K22: =IF(B22="?",ROUND(AVERAGE($B$2:$B$2344),0),B22) -> 1964 | L22: =IF(H22="?",$H$2,H22) -> tier - 3 | M22: =IF(I22="?",$I$2,I22) -> tier - 1 | N22: =IF(J22="?","UNKNOWN",J22) -> R1011 | O22: =IFERROR(INT(YEARFRAC(E22, DATE(2023,6,8))), "") -> 58 | P22: 23562 | Q22: CITY TIER - 2 | R22: COUNTIF | S22: =COUNTIF(M2:M2344,"tier - 2") -> 812
A23: Id98 | B23: 1966 | C23: Aug | D23: 12 | E23: =DATE(K23, MONTH(1 & C23), D23) -> 24331 | F23: 0 | G23: 40373.74 | H23: tier - 1 | I23: tier - 3 | J23: R1011 | K23: =IF(B23="?",ROUND(AVERAGE($B$2:$B$2344),0),B23) -> 1966 | L23: =IF(H23="?",$H$2,H23) -> tier - 1 | M23: =IF(I23="?",$I$2,I23) -> tier - 3 | N23: =IF(J23="?","UNKNOWN",J23) -> R1011 | O23: =IFERROR(INT(YEARFRAC(E23, DATE(2023,6,8))), "") -> 56 | P23: 24331 | Q23: CITY TIER - 3 | R23: COUNTIF | S23: =COUNTIF(M2:M2344,"tier - 3") -> 796
A24: Id979 | B24: 1964 | C24: Jul | D24: 3 | E24: =DATE(K24, MONTH(1 & C24), D24) -> 23561 | F24: 0 | G24: 11363.28 | H24: tier - 3 | I24: tier - 1 | J24: R1013 | K24: =IF(B24="?",ROUND(AVERAGE($B$2:$B$2344),0),B24) -> 1964 | L24: =IF(H24="?",$H$2,H24) -> tier - 3 | M24: =IF(I24="?",$I$2,I24) -> tier - 1 | N24: =IF(J24="?","UNKNOWN",J24) -> R1013 | O24: =IFERROR(INT(YEARFRAC(E24, DATE(2023,6,8))), "") -> 58 | P24: 23561
A25: Id978 | B25: 1964 | C25: Dec | D25: 13 | E25: =DATE(K25, MONTH(1 & C25), D25) -> 23724 | F25: 0 | G25: 11365.95 | H25: tier - 3 | I25: tier - 2 | J25: R1011 | K25: =IF(B25="?",ROUND(AVERAGE($B$2:$B$2344),0),B25) -> 1964 | L25: =IF(H25="?",$H$2,H25) -> tier - 3 | M25: =IF(I25="?",$I$2,I25) -> tier - 2 | N25: =IF(J25="?","UNKNOWN",J25) -> R1011 | O25: =IFERROR(INT(YEARFRAC(E25, DATE(2023,6,8))), "") -> 58 | P25: 23724 | R25: DATE OF COLLECTION
A26: Id977 | B26: 1979 | C26: Jun | D26: 7 | E26: =DATE(K26, MONTH(1 & C26), D26) -> 29013 | F26: 2 | G26: 11369.39 | H26: tier - 3 | I26: tier - 1 | J26: R1026 | K26: =IF(B26="?",ROUND(AVERAGE($B$2:$B$2344),0),B26) -> 1979 | L26: =IF(H26="?",$H$2,H26) -> tier - 3 | M26: =IF(I26="?",$I$2,I26) -> tier - 1 | N26: =IF(J26="?","UNKNOWN",J26) -> R1026 | O26: =IFERROR(INT(YEARFRAC(E26, DATE(2023,6,8))), "") -> 44 | P26: 29013
A27: Id976 | B27: 1972 | C27: Dec | D27: 6 | E27: =DATE(K27, MONTH(1 & C27), D27) -> 26639 | F27: 0 | G27: 11378.57 | H27: tier - 3 | I27: tier - 2 | J27: R1025 | K27: =IF(B27="?",ROUND(AVERAGE($B$2:$B$2344),0),B27) -> 1972 | L27: =IF(H27="?",$H$2,H27) -> tier - 3 | M27: =IF(I27="?",$I$2,I27) -> tier - 2 | N27: =IF(J27="?","UNKNOWN",J27) -> R1025 | O27: =IFERROR(INT(YEARFRAC(E27, DATE(2023,6,8))), "") -> 50 | P27: 26639
A28: Id975 | B28: 1964 | C28: Jun | D28: 13 | E28: =DATE(K28, MONTH(1 & C28), D28) -> 23541 | F28: 0 | G28: 11381.33 | H28: tier - 3 | I28: tier - 2 | J28: R1013 | K28: =IF(B28="?",ROUND(AVERAGE($B$2:$B$2344),0),B28) -> 1964 | L28: =IF(H28="?",$H$2,H28) -> tier - 3 | M28: =IF(I28="?",$I$2,I28) -> tier - 2 | N28: =IF(J28="?","UNKNOWN",J28) -> R1013 | O28: =IFERROR(INT(YEARFRAC(E28, DATE(2023,6,8))), "") -> 58 | P28: 23541 | Q28: 45085
A29: Id974 | B29: 1997 | C29: Jul | D29: 28 | E29: =DATE(K29, MONTH(1 & C29), D29) -> 35639 | F29: 0 | G29: 11388.27 | H29: tier - 3 | I29: tier - 2 | J29: R1026 | K29: =IF(B29="?",ROUND(AVERAGE($B$2:$B$2344),0),B29) -> 1997 | L29: =IF(H29="?",$H$2,H29) -> tier - 3 | M29: =IF(I29="?",$I$2,I29) -> tier - 2 | N29: =IF(J29="?","UNKNOWN",J29) -> R1026 | O29: =IFERROR(INT(YEARFRAC(E29, DATE(2023,6,8))), "") -> 25 | P29: 35639
A30: Id973 | B30: 1967 | C30: Dec | D30: 19 | E30: =DATE(K30, MONTH(1 & C30), D30) -> 24825 | F30: 1 | G30: 11394.07 | H30: tier - 3 | I30: tier - 1 | J30: R1018 | K30: =IF(B30="?",ROUND(AVERAGE($B$2:$B$2344),0),B30) -> 1967 | L30: =IF(H30="?",$H$2,H30) -> tier - 3 | M30: =IF(I30="?",$I$2,I30) -> tier - 1 | N30: =IF(J30="?","UNKNOWN",J30) -> R1018 | O30: =IFERROR(INT(YEARFRAC(E30, DATE(2023,6,8))), "") -> 55 | P30: 24825
A31: Id972 | B31: 1970 | C31: Oct | D31: 2 | E31: =DATE(K31, MONTH(1 & C31), D31) -> 25843 | F31: 2 | G31: 11396.9 | H31: tier - 3 | I31: tier - 3 | J31: R1024 | K31: =IF(B31="?",ROUND(AVERAGE($B$2:$B$2344),0),B31) -> 1970 | L31: =IF(H31="?",$H$2,H31) -> tier - 3 | M31: =IF(I31="?",$I$2,I31) -> tier - 3 | N31: =IF(J31="?","UNKNOWN",J31) -> R1024 | O31: =IFERROR(INT(YEARFRAC(E31, DATE(2023,6,8))), "") -> 52 | P31: 25843
A32: Id971 | B32: 1970 | C32: Oct | D32: 7 | E32: =DATE(K32, MONTH(1 & C32), D32) -> 25848 | F32: 3 | G32: 11411.69 | H32: tier - 3 | I32: tier - 2 | J32: R1011 | K32: =IF(B32="?",ROUND(AVERAGE($B$2:$B$2344),0),B32) -> 1970 | L32: =IF(H32="?",$H$2,H32) -> tier - 3 | M32: =IF(I32="?",$I$2,I32) -> tier - 2 | N32: =IF(J32="?","UNKNOWN",J32) -> R1011 | O32: =IFERROR(INT(YEARFRAC(E32, DATE(2023,6,8))), "") -> 52 | P32: 25848
A33: Id970 | B33: 1983 | C33: Oct | D33: 23 | E33: =DATE(K33, MONTH(1 & C33), D33) -> 30612 | F33: 3 | G33: 11412.02 | H33: tier - 3 | I33: tier - 1 | J33: R1021 | K33: =IF(B33="?",ROUND(AVERAGE($B$2:$B$2344),0),B33) -> 1983 | L33: =IF(H33="?",$H$2,H33) -> tier - 3 | M33: =IF(I33="?",$I$2,I33) -> tier - 1 | N33: =IF(J33="?","UNKNOWN",J33) -> R1021 | O33: =IFERROR(INT(YEARFRAC(E33, DATE(2023,6,8))), "") -> 39 | P33: 30612
A34: Id97 | B34: 1985 | C34: Nov | D34: 3 | E34: =DATE(K34, MONTH(1 & C34), D34) -> 31354 | F34: 0 | G34: 40419.02 | H34: tier - 1 | I34: tier - 2 | J34: R1013 | K34: =IF(B34="?",ROUND(AVERAGE($B$2:$B$2344),0),B34) -> 1985 | L34: =IF(H34="?",$H$2,H34) -> tier - 1 | M34: =IF(I34="?",$I$2,I34) -> tier - 2 | N34: =IF(J34="?","UNKNOWN",J34) -> R1013 | O34: =IFERROR(INT(YEARFRAC(E34, DATE(2023,6,8))), "") -> 37 | P34: 31354
A35: Id969 | B35: 1985 | C35: Jun | D35: 9 | E35: =DATE(K35, MONTH(1 & C35), D35) -> 31207 | F35: 3 | G35: 11419.49 | H35: tier - 3 | I35: tier - 1 | J35: R1012 | K35: =IF(B35="?",ROUND(AVERAGE($B$2:$B$2344),0),B35) -> 1985 | L35: =IF(H35="?",$H$2,H35) -> tier - 3 | M35: =IF(I35="?",$I$2,I35) -> tier - 1 | N35: =IF(J35="?","UNKNOWN",J35) -> R1012 | O35: =IFERROR(INT(YEARFRAC(E35, DATE(2023,6,8))), "") -> 37 | P35: 31207
A36: Id968 | B36: 1980 | C36: Jul | D36: 17 | E36: =DATE(K36, MONTH(1 & C36), D36) -> 29419 | F36: 2 | G36: 11435.74 | H36: tier - 3 | I36: tier - 3 | J36: R1021 | K36: =IF(B36="?",ROUND(AVERAGE($B$2:$B$2344),0),B36) -> 1980 | L36: =IF(H36="?",$H$2,H36) -> tier - 3 | M36: =IF(I36="?",$I$2,I36) -> tier - 3 | N36: =IF(J36="?","UNKNOWN",J36) -> R1021 | O36: =IFERROR(INT(YEARFRAC(E36, DATE(2023,6,8))), "") -> 42 | P36: 29419
A37: Id967 | B37: 1971 | C37: Sep | D37: 12 | E37: =DATE(K37, MONTH(1 & C37), D37) -> 26188 | F37: 3 | G37: 11436.74 | H37: tier - 3 | I37: tier - 3 | J37: R1012 | K37: =IF(B37="?",ROUND(AVERAGE($B$2:$B$2344),0),B37) -> 1971 | L37: =IF(H37="?",$H$2,H37) -> tier - 3 | M37: =IF(I37="?",$I$2,I37) -> tier - 3 | N37: =IF(J37="?","UNKNOWN",J37) -> R1012 | O37: =IFERROR(INT(YEARFRAC(E37, DATE(2023,6,8))), "") -> 51 | P37: 26188
A38: Id966 | B38: 1966 | C38: Jun | D38: 14 | E38: =DATE(K38, MONTH(1 & C38), D38) -> 24272 | F38: 0 | G38: 11454.02 | H38: tier - 3 | I38: tier - 1 | J38: R1012 | K38: =IF(B38="?",ROUND(AVERAGE($B$2:$B$2344),0),B38) -> 1966 | L38: =IF(H38="?",$H$2,H38) -> tier - 3 | M38: =IF(I38="?",$I$2,I38) -> tier - 1 | N38: =IF(J38="?","UNKNOWN",J38) -> R1012 | O38: =IFERROR(INT(YEARFRAC(E38, DATE(2023,6,8))), "") -> 56 | P38: 24272
A39: Id965 | B39: 1965 | C39: Jun | D39: 23 | E39: =DATE(K39, MONTH(1 & C39), D39) -> 23916 | F39: 0 | G39: 11455.28 | H39: tier - 3 | I39: tier - 2 | J39: R1011 | K39: =IF(B39="?",ROUND(AVERAGE($B$2:$B$2344),0),B39) -> 1965 | L39: =IF(H39="?",$H$2,H39) -> tier - 3 | M39: =IF(I39="?",$I$2,I39) -> tier - 2 | N39: =IF(J39="?","UNKNOWN",J39) -> R1011 | O39: =IFERROR(INT(YEARFRAC(E39, DATE(2023,6,8))), "") -> 57 | P39: 23916
A40: Id964 | B40: 1966 | C40: Sep | D40: 7 | E40: =DATE(K40, MONTH(1 & C40), D40) -> 24357 | F40: 0 | G40: 11478.14 | H40: tier - 3 | I40: tier - 2 | J40: R1025 | K40: =IF(B40="?",ROUND(AVERAGE($B$2:$B$2344),0),B40) -> 1966 | L40: =IF(H40="?",$H$2,H40) -> tier - 3 | M40: =IF(I40="?",$I$2,I40) -> tier - 2 | N40: =IF(J40="?","UNKNOWN",J40) -> R1025 | O40: =IFERROR(INT(YEARFRAC(E40, DATE(2023,6,8))), "") -> 56 | P40: 24357
...

Sheet Pivot table
A2: Total customers count, | C2: Total hospitalisation count, | F2: Total healthcare costs, | I2: Average costs and medical metrics
A3: Count of Customer | C3: Row Labels | D3: Count of Hospital Tier | F3: Row Labels | G3: Sum of Charges | I3: Row Labels | J3: Average of Charges
A4: 2335 | C4: tier - 1 | D4: 305 | F4: tier - 1 | G4: 9159976.4 | I4: tier - 1 | J4: 30032.709
C5: tier - 2 | D5: 1336 | F5: tier - 2 | G5: 15874466 | I5: tier - 2 | J5: 11882.085
C6: tier - 3 | D6: 693 | F6: tier - 3 | G6: 6557352.6 | I6: tier - 3 | J6: 9462.2693
C7: Grand Total | D7: 2334 | F7: Grand Total | G7: 31591795 | I7: Grand Total | J7: 13535.473

Sheet Healthcare
A1: Customer id | B1: First Name | C1: BMI | D1: HBA1C | E1: Heart Issues | F1: Any Transplants | G1: Cancer History | H1: Number Of Major Surgeries | I1: Smoker | J1: Weight Status | K1: Date Of Birth | L1: Charges | M1: Hospital Tier | N1: City Tier | O1: State ID | P1: Age
A2: Id1 | B2: =VLOOKUP($A2,'Customer Names'!$A:$D,3, FALSE) -> Hawks | C2: =VLOOKUP($A2,'Medical Examinations'!$A:$D, 2, FALSE) -> 47.41 | D2: =VLOOKUP($A2, 'Medical Examinations'!$A:$D,3, FALSE) -> 7.47 | E2: =VLOOKUP($A2, 'Medical Examinations'!$A:$D, 4, FALSE) -> No | F2: =VLOOKUP($A2, 'Medical Examinations'!$A:$J, 5, FALSE) -> No | G2: =VLOOKUP($A2, 'Medical Examinations'!$A:$I, 6, FALSE) -> No | H2: =VLOOKUP($A2,'Medical Examinations'!$A:$L,10, FALSE) -> 0 | I2: =VLOOKUP($A2, 'Medical Examinations'!$A:$J, 9, FALSE) -> Yes | J2: =VLOOKUP($A2, 'Medical Examinations'!$A:$P, 11, FALSE) -> OBESITY | K2: 31401 | L2: =VLOOKUP($A2, 'Hospitalisation Details'!$A:$H, 7, FALSE) -> 63770.43 | M2: =VLOOKUP($A2, 'Hospitalisation Details'!$A:$L, 12, FALSE) -> tier - 1 | N2: =VLOOKUP($A2, 'Hospitalisation Details'!$A:$M, 13, FALSE) -> tier - 3 | O2: =VLOOKUP($A2, 'Hospitalisation Details'!$A:$N, 14, FALSE) -> R1013 | P2: =VLOOKUP($A2, 'Hospitalisation Details'!$A:$O, 15, FALSE) -> 54
A3: Id2 | B3: =VLOOKUP($A3,'Customer Names'!$A:$D,3, FALSE) -> Lehner | C3: =VLOOKUP($A3,'Medical Examinations'!$A:$D, 2, FALSE) -> 30.36 | D3: =VLOOKUP($A3, 'Medical Examinations'!$A:$D,3, FALSE) -> 5.77 | E3: =VLOOKUP($A3, 'Medical Examinations'!$A:$D, 4, FALSE) -> No | F3: =VLOOKUP($A3, 'Medical Examinations'!$A:$J, 5, FALSE) -> No | G3: =VLOOKUP($A3, 'Medical Examinations'!$A:$I, 6, FALSE) -> No | H3: =VLOOKUP($A3,'Medical Examinations'!$A:$L,10, FALSE) -> 0 | I3: =VLOOKUP($A3, 'Medical Examinations'!$A:$J, 9, FALSE) -> Yes | J3: =VLOOKUP($A3, 'Medical Examinations'!$A:$P, 11, FALSE) -> OBESITY | K3: 33564 | L3: =VLOOKUP($A3, 'Hospitalisation Details'!$A:$H, 7, FALSE) -> 62592.87 | M3: =VLOOKUP($A3, 'Hospitalisation Details'!$A:$L, 12, FALSE) -> tier - 2 | N3: =VLOOKUP($A3, 'Hospitalisation Details'!$A:$M, 13, FALSE) -> tier - 3 | O3: =VLOOKUP($A3, 'Hospitalisation Details'!$A:$N, 14, FALSE) -> R1013 | P3: =VLOOKUP($A3, 'Hospitalisation Details'!$A:$O, 15, FALSE) -> 46
A4: Id3 | B4: =VLOOKUP($A4,'Customer Names'!$A:$D,3, FALSE) -> Lu | C4: =VLOOKUP($A4,'Medical Examinations'!$A:$D, 2, FALSE) -> 34.485 | D4: =VLOOKUP($A4, 'Medical Examinations'!$A:$D,3, FALSE) -> 11.87 | E4: =VLOOKUP($A4, 'Medical Examinations'!$A:$D, 4, FALSE) -> Yes | F4: =VLOOKUP($A4, 'Medical Examinations'!$A:$J, 5, FALSE) -> No | G4: =VLOOKUP($A4, 'Medical Examinations'!$A:$I, 6, FALSE) -> No | H4: =VLOOKUP($A4,'Medical Examinations'!$A:$L,10, FALSE) -> 2 | I4: =VLOOKUP($A4, 'Medical Examinations'!$A:$J, 9, FALSE) -> Yes | J4: =VLOOKUP($A4, 'Medical Examinations'!$A:$P, 11, FALSE) -> OBESITY | K4: 33883 | L4: =VLOOKUP($A4, 'Hospitalisation Details'!$A:$H, 7, FALSE) -> 60021.4 | M4: =VLOOKUP($A4, 'Hospitalisation Details'!$A:$L, 12, FALSE) -> tier - 1 | N4: =VLOOKUP($A4, 'Hospitalisation Details'!$A:$M, 13, FALSE) -> tier - 1 | O4: =VLOOKUP($A4, 'Hospitalisation Details'!$A:$N, 14, FALSE) -> R1012 | P4: =VLOOKUP($A4, 'Hospitalisation Details'!$A:$O, 15, FALSE) -> 52 | R4: Healthcare statistics
A5: Id4 | B5: =VLOOKUP($A5,'Customer Names'!$A:$D,3, FALSE) -> Osborne | C5: =VLOOKUP($A5,'Medical Examinations'!$A:$D, 2, FALSE) -> 38.095 | D5: =VLOOKUP($A5, 'Medical Examinations'!$A:$D,3, FALSE) -> 6.05 | E5: =VLOOKUP($A5, 'Medical Examinations'!$A:$D, 4, FALSE) -> No | F5: =VLOOKUP($A5, 'Medical Examinations'!$A:$J, 5, FALSE) -> No | G5: =VLOOKUP($A5, 'Medical Examinations'!$A:$I, 6, FALSE) -> No | H5: =VLOOKUP($A5,'Medical Examinations'!$A:$L,10, FALSE) -> 0 | I5: =VLOOKUP($A5, 'Medical Examinations'!$A:$J, 9, FALSE) -> Yes | J5: =VLOOKUP($A5, 'Medical Examinations'!$A:$P, 11, FALSE) -> OBESITY | K5: 36320 | L5: =VLOOKUP($A5, 'Hospitalisation Details'!$A:$H, 7, FALSE) -> 58571.07 | M5: =VLOOKUP($A5, 'Hospitalisation Details'!$A:$L, 12, FALSE) -> tier - 1 | N5: =VLOOKUP($A5, 'Hospitalisation Details'!$A:$M, 13, FALSE) -> tier - 3 | O5: =VLOOKUP($A5, 'Hospitalisation Details'!$A:$N, 14, FALSE) -> R1024 | P5: =VLOOKUP($A5, 'Hospitalisation Details'!$A:$O, 15, FALSE) -> 32 | R5: Total customers count | S5: =SUBTOTAL(103,Healthcare!$A$2:$A$2335) -> 2334
A6: Id5 | B6: =VLOOKUP($A6,'Customer Names'!$A:$D,3, FALSE) -> Kadala | C6: =VLOOKUP($A6,'Medical Examinations'!$A:$D, 2, FALSE) -> 35.53 | D6: =VLOOKUP($A6, 'Medical Examinations'!$A:$D,3, FALSE) -> 5.45 | E6: =VLOOKUP($A6, 'Medical Examinations'!$A:$D, 4, FALSE) -> No | F6: =VLOOKUP($A6, 'Medical Examinations'!$A:$J, 5, FALSE) -> No | G6: =VLOOKUP($A6, 'Medical Examinations'!$A:$I, 6, FALSE) -> No | H6: =VLOOKUP($A6,'Medical Examinations'!$A:$L,10, FALSE) -> 0 | I6: =VLOOKUP($A6, 'Medical Examinations'!$A:$J, 9, FALSE) -> Yes | J6: =VLOOKUP($A6, 'Medical Examinations'!$A:$P, 11, FALSE) -> OBESITY | K6: 36812 | L6: =VLOOKUP($A6, 'Hospitalisation Details'!$A:$H, 7, FALSE) -> 55135.4 | M6: =VLOOKUP($A6, 'Hospitalisation Details'!$A:$L, 12, FALSE) -> tier - 1 | N6: =VLOOKUP($A6, 'Hospitalisation Details'!$A:$M, 13, FALSE) -> tier - 2 | O6: =VLOOKUP($A6, 'Hospitalisation Details'!$A:$N, 14, FALSE) -> R1012 | P6: =VLOOKUP($A6, 'Hospitalisation Details'!$A:$O, 15, FALSE) -> 33 | R6: Total hospitalisation count | S6: =SUBTOTAL(103,Healthcare!$B$2:$B$2335) -> 2334
A7: Id6 | B7: =VLOOKUP($A7,'Customer Names'!$A:$D,3, FALSE) -> Baker | C7: =VLOOKUP($A7,'Medical Examinations'!$A:$D, 2, FALSE) -> 32.8 | D7: =VLOOKUP($A7, 'Medical Examinations'!$A:$D,3, FALSE) -> 6.59 | E7: =VLOOKUP($A7, 'Medical Examinations'!$A:$D, 4, FALSE) -> No | F7: =VLOOKUP($A7, 'Medical Examinations'!$A:$J, 5, FALSE) -> No | G7: =VLOOKUP($A7, 'Medical Examinations'!$A:$I, 6, FALSE) -> No | H7: =VLOOKUP($A7,'Medical Examinations'!$A:$L,10, FALSE) -> 0 | I7: =VLOOKUP($A7, 'Medical Examinations'!$A:$J, 9, FALSE) -> Yes | J7: =VLOOKUP($A7, 'Medical Examinations'!$A:$P, 11, FALSE) -> OBESITY | K7: 38297 | L7: =VLOOKUP($A7, 'Hospitalisation Details'!$A:$H, 7, FALSE) -> 52590.83 | M7: =VLOOKUP($A7, 'Hospitalisation Details'!$A:$L, 12, FALSE) -> tier - 1 | N7: =VLOOKUP($A7, 'Hospitalisation Details'!$A:$M, 13, FALSE) -> tier - 3 | O7: =VLOOKUP($A7, 'Hospitalisation Details'!$A:$N, 14, FALSE) -> R1011 | P7: =VLOOKUP($A7, 'Hospitalisation Details'!$A:$O, 15, FALSE) -> 60 | R7: Total healthcare costs | S7: =SUBTOTAL(109,Healthcare!$L$2:$L$2335) -> 31591795
A8: Id7 | B8: =VLOOKUP($A8,'Customer Names'!$A:$D,3, FALSE) -> Macpherson | C8: =VLOOKUP($A8,'Medical Examinations'!$A:$D, 2, FALSE) -> 36.4 | D8: =VLOOKUP($A8, 'Medical Examinations'!$A:$D,3, FALSE) -> 6.07 | E8: =VLOOKUP($A8, 'Medical Examinations'!$A:$D, 4, FALSE) -> No | F8: =VLOOKUP($A8, 'Medical Examinations'!$A:$J, 5, FALSE) -> No | G8: =VLOOKUP($A8, 'Medical Examinations'!$A:$I, 6, FALSE) -> No | H8: =VLOOKUP($A8,'Medical Examinations'!$A:$L,10, FALSE) -> 0 | I8: =VLOOKUP($A8, 'Medical Examinations'!$A:$J, 9, FALSE) -> Yes | J8: =VLOOKUP($A8, 'Medical Examinations'!$A:$P, 11, FALSE) -> OBESITY | K8: 25123 | L8: =VLOOKUP($A8, 'Hospitalisation Details'!$A:$H, 7, FALSE) -> 51194.56 | M8: =VLOOKUP($A8, 'Hospitalisation Details'!$A:$L, 12, FALSE) -> tier - 1 | N8: =VLOOKUP($A8, 'Hospitalisation Details'!$A:$M, 13, FALSE) -> tier - 3 | O8: =VLOOKUP($A8, 'Hospitalisation Details'!$A:$N, 14, FALSE) -> R1011 | P8: =VLOOKUP($A8, 'Hospitalisation Details'!$A:$O, 15, FALSE) -> 28 | R8: Average costs and medical metrics | S8: =SUBTOTAL(101,Healthcare!$L$2:$L$2335) -> 13535.473
A9: Id8 | B9: =VLOOKUP($A9,'Customer Names'!$A:$D,3, FALSE) -> Hallman | C9: =VLOOKUP($A9,'Medical Examinations'!$A:$D, 2, FALSE) -> 36.96 | D9: =VLOOKUP($A9, 'Medical Examinations'!$A:$D,3, FALSE) -> 7.93 | E9: =VLOOKUP($A9, 'Medical Examinations'!$A:$D, 4, FALSE) -> No | F9: =VLOOKUP($A9, 'Medical Examinations'!$A:$J, 5, FALSE) -> No | G9: =VLOOKUP($A9, 'Medical Examinations'!$A:$I, 6, FALSE) -> No | H9: =VLOOKUP($A9,'Medical Examinations'!$A:$L,10, FALSE) -> 3 | I9: =VLOOKUP($A9, 'Medical Examinations'!$A:$J, 9, FALSE) -> Yes | J9: =VLOOKUP($A9, 'Medical Examinations'!$A:$P, 11, FALSE) -> OBESITY | K9: 28853 | L9: =VLOOKUP($A9, 'Hospitalisation Details'!$A:$H, 7, FALSE) -> 49577.66 | M9: =VLOOKUP($A9, 'Hospitalisation Details'!$A:$L, 12, FALSE) -> tier - 2 | N9: =VLOOKUP($A9, 'Hospitalisation Details'!$A:$M, 13, FALSE) -> tier - 2 | O9: =VLOOKUP($A9, 'Hospitalisation Details'!$A:$N, 14, FALSE) -> R1013 | P9: =VLOOKUP($A9, 'Hospitalisation Details'!$A:$O, 15, FALSE) -> 64
A10: Id9 | B10: =VLOOKUP($A10,'Customer Names'!$A:$D,3, FALSE) -> Moran | C10: =VLOOKUP($A10,'Medical Examinations'!$A:$D, 2, FALSE) -> 41.14 | D10: =VLOOKUP($A10, 'Medical Examinations'!$A:$D,3, FALSE) -> 9.58 | E10: =VLOOKUP($A10, 'Medical Examinations'!$A:$D, 4, FALSE) -> Yes | F10: =VLOOKUP($A10, 'Medical Examinations'!$A:$J, 5, FALSE) -> No | G10: =VLOOKUP($A10, 'Medical Examinations'!$A:$I, 6, FALSE) -> Yes | H10: =VLOOKUP($A10,'Medical Examinations'!$A:$L,10, FALSE) -> 1 | I10: =VLOOKUP($A10, 'Medical Examinations'!$A:$J, 9, FALSE) -> Yes | J10: =VLOOKUP($A10, 'Medical Examinations'!$A:$P, 11, FALSE) -> OBESITY | K10: 28303 | L10: =VLOOKUP($A10, 'Hospitalisation Details'!$A:$H, 7, FALSE) -> 48970.25 | M10: =VLOOKUP($A10, 'Hospitalisation Details'!$A:$L, 12, FALSE) -> tier - 1 | N10: =VLOOKUP($A10, 'Hospitalisation Details'!$A:$M, 13, FALSE) -> tier - 2 | O10: =VLOOKUP($A10, 'Hospitalisation Details'!$A:$N, 14, FALSE) -> R1013 | P10: =VLOOKUP($A10, 'Hospitalisation Details'!$A:$O, 15, FALSE) -> 59
A11: Id10 | B11: =VLOOKUP($A11,'Customer Names'!$A:$D,3, FALSE) -> Benner | C11: =VLOOKUP($A11,'Medical Examinations'!$A:$D, 2, FALSE) -> 38.06 | D11: =VLOOKUP($A11, 'Medical Examinations'!$A:$D,3, FALSE) -> 10.79 | E11: =VLOOKUP($A11, 'Medical Examinations'!$A:$D, 4, FALSE) -> No | F11: =VLOOKUP($A11, 'Medical Examinations'!$A:$J, 5, FALSE) -> No | G11: =VLOOKUP($A11, 'Medical Examinations'!$A:$I, 6, FALSE) -> No | H11: =VLOOKUP($A11,'Medical Examinations'!$A:$L,10, FALSE) -> 0 | I11: =VLOOKUP($A11, 'Medical Examinations'!$A:$J, 9, FALSE) -> Yes | J11: =VLOOKUP($A11, 'Medical Examinations'!$A:$P, 11, FALSE) -> OBESITY | K11: 32859 | L11: =VLOOKUP($A11, 'Hospitalisation Details'!$A:$H, 7, FALSE) -> 48885.14 | M11: =VLOOKUP($A11, 'Hospitalisation Details'!$A:$L, 12, FALSE) -> tier - 1 | N11: =VLOOKUP($A11, 'Hospitalisation Details'!$A:$M, 13, FALSE) -> tier - 2 | O11: =VLOOKUP($A11, 'Hospitalisation Details'!$A:$N, 14, FALSE) -> R1013 | P11: =VLOOKUP($A11, 'Hospitalisation Details'!$A:$O, 15, FALSE) -> 44
A12: Id11 | B12: =VLOOKUP($A12,'Customer Names'!$A:$D,3, FALSE) -> Fierr | C12: =VLOOKUP($A12,'Medical Examinations'!$A:$D, 2, FALSE) -> 37.7 | D12: =VLOOKUP($A12, 'Medical Examinations'!$A:$D,3, FALSE) -> 5.96 | E12: =VLOOKUP($A12, 'Medical Examinations'!$A:$D, 4, FALSE) -> Yes | F12: =VLOOKUP($A12, 'Medical Examinations'!$A:$J, 5, FALSE) -> No | G12: =VLOOKUP($A12, 'Medical Examinations'!$A:$I, 6, FALSE) -> No | H12: =VLOOKUP($A12,'Medical Examinations'!$A:$L,10, FALSE) -> 2 | I12: =VLOOKUP($A12, 'Medical Examinations'!$A:$J, 9, FALSE) -> Yes | J12: =VLOOKUP($A12, 'Medical Examinations'!$A:$P, 11, FALSE) -> OBESITY | K12: 25567 | L12: =VLOOKUP($A12, 'Hospitalisation Details'!$A:$H, 7, FALSE) -> 48824.45 | M12: =VLOOKUP($A12, 'Hospitalisation Details'!$A:$L, 12, FALSE) -> tier - 2 | N12: =VLOOKUP($A12, 'Hospitalisation Details'!$A:$M, 13, FALSE) -> tier - 1 | O12: =VLOOKUP($A12, 'Hospitalisation Details'!$A:$N, 14, FALSE) -> R1011 | P12: =VLOOKUP($A12, 'Hospitalisation Details'!$A:$O, 15, FALSE) -> 63
A13: Id12 | B13: =VLOOKUP($A13,'Customer Names'!$A:$D,3, FALSE) -> Franz | C13: =VLOOKUP($A13,'Medical Examinations'!$A:$D, 2, FALSE) -> 42.13 | D13: =VLOOKUP($A13, 'Medical Examinations'!$A:$D,3, FALSE) -> 11.9 | E13: =VLOOKUP($A13, 'Medical Examinations'!$A:$D, 4, FALSE) -> No | F13: =VLOOKUP($A13, 'Medical Examinations'!$A:$J, 5, FALSE) -> No | G13: =VLOOKUP($A13, 'Medical Examinations'!$A:$I, 6, FALSE) -> No | H13: =VLOOKUP($A13,'Medical Examinations'!$A:$L,10, FALSE) -> 0 | I13: =VLOOKUP($A13, 'Medical Examinations'!$A:$J, 9, FALSE) -> Yes | J13: =VLOOKUP($A13, 'Medical Examinations'!$A:$P, 11, FALSE) -> OBESITY | K13: 27939 | L13: =VLOOKUP($A13, 'Hospitalisation Details'!$A:$H, 7, FALSE) -> 48675.52 | M13: =VLOOKUP($A13, 'Hospitalisation Details'!$A:$L, 12, FALSE) -> tier - 1 | N13: =VLOOKUP($A13, 'Hospitalisation Details'!$A:$M, 13, FALSE) -> tier - 2 | O13: =VLOOKUP($A13, 'Hospitalisation Details'!$A:$N, 14, FALSE) -> R1013 | P13: =VLOOKUP($A13, 'Hospitalisation Details'!$A:$O, 15, FALSE) -> 57
A14: Id13 | B14: =VLOOKUP($A14,'Customer Names'!$A:$D,3, FALSE) -> Foster | C14: =VLOOKUP($A14,'Medical Examinations'!$A:$D, 2, FALSE) -> 40.92 | D14: =VLOOKUP($A14, 'Medical Examinations'!$A:$D,3, FALSE) -> 8.41 | E14: =VLOOKUP($A14, 'Medical Examinations'!$A:$D, 4, FALSE) -> No | F14: =VLOOKUP($A14, 'Medical Examinations'!$A:$J, 5, FALSE) -> No | G14: =VLOOKUP($A14, 'Medical Examinations'!$A:$I, 6, FALSE) -> No | H14: =VLOOKUP($A14,'Medical Examinations'!$A:$L,10, FALSE) -> 0 | I14: =VLOOKUP($A14, 'Medical Examinations'!$A:$J, 9, FALSE) -> Yes | J14: =VLOOKUP($A14, 'Medical Examinations'!$A:$P, 11, FALSE) -> OBESITY | K14: 25733 | L14: =VLOOKUP($A14, 'Hospitalisation Details'!$A:$H, 7, FALSE) -> 48673.56 | M14: =VLOOKUP($A14, 'Hospitalisation Details'!$A:$L, 12, FALSE) -> tier - 1 | N14: =VLOOKUP($A14, 'Hospitalisation Details'!$A:$M, 13, FALSE) -> tier - 2 | O14: =VLOOKUP($A14, 'Hospitalisation Details'!$A:$N, 14, FALSE) -> R1013 | P14: =VLOOKUP($A14, 'Hospitalisation Details'!$A:$O, 15, FALSE) -> 60
A15: Id14 | B15: =VLOOKUP($A15,'Customer Names'!$A:$D,3, FALSE) -> Tenorio | C15: =VLOOKUP($A15,'Medical Examinations'!$A:$D, 2, FALSE) -> 40.565 | D15: =VLOOKUP($A15, 'Medical Examinations'!$A:$D,3, FALSE) -> 7.02 | E15: =VLOOKUP($A15, 'Medical Examinations'!$A:$D, 4, FALSE) -> No | F15: =VLOOKUP($A15, 'Medical Examinations'!$A:$J, 5, FALSE) -> No | G15: =VLOOKUP($A15, 'Medical Examinations'!$A:$I, 6, FALSE) -> No | H15: =VLOOKUP($A15,'Medical Examinations'!$A:$L,10, FALSE) -> 0 | I15: =VLOOKUP($A15, 'Medical Examinations'!$A:$J, 9, FALSE) -> Yes | J15: =VLOOKUP($A15, 'Medical Examinations'!$A:$P, 11, FALSE) -> OBESITY | K15: 26545 | L15: =VLOOKUP($A15, 'Hospitalisation Details'!$A:$H, 7, FALSE) -> 48549.18 | M15: =VLOOKUP($A15, 'Hospitalisation Details'!$A:$L, 12, FALSE) -> tier - 1 | N15: =VLOOKUP($A15, 'Hospitalisation Details'!$A:$M, 13, FALSE) -> tier - 3 | O15: =VLOOKUP($A15, 'Hospitalisation Details'!$A:$N, 14, FALSE) -> R1016 | P15: =VLOOKUP($A15, 'Hospitalisation Details'!$A:$O, 15, FALSE) -> 54
A16: Id15 | B16: =VLOOKUP($A16,'Customer Names'!$A:$D,3, FALSE) -> Rios | C16: =VLOOKUP($A16,'Medical Examinations'!$A:$D, 2, FALSE) -> 36.385 | D16: =VLOOKUP($A16, 'Medical Examinations'!$A:$D,3, FALSE) -> 7.59 | E16: =VLOOKUP($A16, 'Medical Examinations'!$A:$D, 4, FALSE) -> Yes | F16: =VLOOKUP($A16, 'Medical Examinations'!$A:$J, 5, FALSE) -> No | G16: =VLOOKUP($A16, 'Medical Examinations'!$A:$I, 6, FALSE) -> No | H16: =VLOOKUP($A16,'Medical Examinations'!$A:$L,10, FALSE) -> 2 | I16: =VLOOKUP($A16, 'Medical Examinations'!$A:$J, 9, FALSE) -> Yes | J16: =VLOOKUP($A16, 'Medical Examinations'!$A:$P, 11, FALSE) -> OBESITY | K16: 24325 | L16: =VLOOKUP($A16, 'Hospitalisation Details'!$A:$H, 7, FALSE) -> 48517.56 | M16: =VLOOKUP($A16, 'Hospitalisation Details'!$A:$L, 12, FALSE) -> tier - 1 | N16: =VLOOKUP($A16, 'Hospitalisation Details'!$A:$M, 13, FALSE) -> tier - 3 | O16: =VLOOKUP($A16, 'Hospitalisation Details'!$A:$N, 14, FALSE) -> R1024 | P16: =VLOOKUP($A16, 'Hospitalisation Details'!$A:$O, 15, FALSE) -> 61
A17: Id16 | B17: =VLOOKUP($A17,'Customer Names'!$A:$D,3, FALSE) -> Viau-Dupuis | C17: =VLOOKUP($A17,'Medical Examinations'!$A:$D, 2, FALSE) -> 39.9 | D17: =VLOOKUP($A17, 'Medical Examinations'!$A:$D,3, FALSE) -> 11.32 | E17: =VLOOKUP($A17, 'Medical Examinations'!$A:$D, 4, FALSE) -> No | F17: =VLOOKUP($A17, 'Medical Examinations'!$A:$J, 5, FALSE) -> No | G17: =VLOOKUP($A17, 'Medical Examinations'!$A:$I, 6, FALSE) -> No | H17: =VLOOKUP($A17,'Medical Examinations'!$A:$L,10, FALSE) -> 0 | I17: =VLOOKUP($A17, 'Medical Examinations'!$A:$J, 9, FALSE) -> Yes | J17: =VLOOKUP($A17, 'Medical Examinations'!$A:$P, 11, FALSE) -> OBESITY | K17: 25379 | L17: =VLOOKUP($A17, 'Hospitalisation Details'!$A:$H, 7, FALSE) -> 48173.36 | M17: =VLOOKUP($A17, 'Hospitalisation Details'!$A:$L, 12, FALSE) -> tier - 1 | N17: =VLOOKUP($A17, 'Hospitalisation Details'!$A:$M, 13, FALSE) -> tier - 3 | O17: =VLOOKUP($A17, 'Hospitalisation Details'!$A:$N, 14, FALSE) -> R1011 | P17: =VLOOKUP($A17, 'Hospitalisation Details'!$A:$O, 15, FALSE) -> 60
A18: Id17 | B18: =VLOOKUP($A18,'Customer Names'!$A:$D,3, FALSE) -> Cronin | C18: =VLOOKUP($A18,'Medical Examinations'!$A:$D, 2, FALSE) -> 33.8 | D18: =VLOOKUP($A18, 'Medical Examinations'!$A:$D,3, FALSE) -> 7.67 | E18: =VLOOKUP($A18, 'Medical Examinations'!$A:$D, 4, FALSE) -> No | F18: =VLOOKUP($A18, 'Medical Examinations'!$A:$J, 5, FALSE) -> No | G18: =VLOOKUP($A18, 'Medical Examinations'!$A:$I, 6, FALSE) -> No | H18: =VLOOKUP($A18,'Medical Examinations'!$A:$L,10, FALSE) -> 3 | I18: =VLOOKUP($A18, 'Medical Examinations'!$A:$J, 9, FALSE) -> Yes | J18: =VLOOKUP($A18, 'Medical Examinations'!$A:$P, 11, FALSE) -> OBESITY | K18: 25537 | L18: =VLOOKUP($A18, 'Hospitalisation Details'!$A:$H, 7, FALSE) -> 47928.03 | M18: =VLOOKUP($A18, 'Hospitalisation Details'!$A:$L, 12, FALSE) -> tier - 2 | N18: =VLOOKUP($A18, 'Hospitalisation Details'!$A:$M, 13, FALSE) -> tier - 3 | O18: =VLOOKUP($A18, 'Hospitalisation Details'!$A:$N, 14, FALSE) -> R1011 | P18: =VLOOKUP($A18, 'Hospitalisation Details'!$A:$O, 15, FALSE) -> 64
A19: Id18 | B19: =VLOOKUP($A19,'Customer Names'!$A:$D,3, FALSE) -> Noordstar | C19: =VLOOKUP($A19,'Medical Examinations'!$A:$D, 2, FALSE) -> 36.765 | D19: =VLOOKUP($A19, 'Medical Examinations'!$A:$D,3, FALSE) -> 7.29 | E19: =VLOOKUP($A19, 'Medical Examinations'!$A:$D, 4, FALSE) -> Yes | F19: =VLOOKUP($A19, 'Medical Examinations'!$A:$J, 5, FALSE) -> No | G19: =VLOOKUP($A19, 'Medical Examinations'!$A:$I, 6, FALSE) -> Yes | H19: =VLOOKUP($A19,'Medical Examinations'!$A:$L,10, FALSE) -> 1 | I19: =VLOOKUP($A19, 'Medical Examinations'!$A:$J, 9, FALSE) -> Yes | J19: =VLOOKUP($A19, 'Medical Examinations'!$A:$P, 11, FALSE) -> OBESITY | K19: 29453 | L19: =VLOOKUP($A19, 'Hospitalisation Details'!$A:$H, 7, FALSE) -> 47896.79 | M19: =VLOOKUP($A19, 'Hospitalisation Details'!$A:$L, 12, FALSE) -> tier - 1 | N19: =VLOOKUP($A19, 'Hospitalisation Details'!$A:$M, 13, FALSE) -> tier - 3 | O19: =VLOOKUP($A19, 'Hospitalisation Details'!$A:$N, 14, FALSE) -> R1024 | P19: =VLOOKUP($A19, 'Hospitalisation Details'!$A:$O, 15, FALSE) -> 59
A20: Id19 | B20: =VLOOKUP($A20,'Customer Names'!$A:$D,3, FALSE) -> Boudalia | C20: =VLOOKUP($A20,'Medical Examinations'!$A:$D, 2, FALSE) -> 36.955 | D20: =VLOOKUP($A20, 'Medical Examinations'!$A:$D,3, FALSE) -> 4.72 | E20: =VLOOKUP($A20, 'Medical Examinations'!$A:$D, 4, FALSE) -> Yes | F20: =VLOOKUP($A20, 'Medical Examinations'!$A:$J, 5, FALSE) -> No | G20: =VLOOKUP($A20, 'Medical Examinations'!$A:$I, 6, FALSE) -> No | H20: =VLOOKUP($A20,'Medical Examinations'!$A:$L,10, FALSE) -> 1 | I20: =VLOOKUP($A20, 'Medical Examinations'!$A:$J, 9, FALSE) -> Yes | J20: =VLOOKUP($A20, 'Medical Examinations'!$A:$P, 11, FALSE) -> OBESITY | K20: 24293 | L20: =VLOOKUP($A20, 'Hospitalisation Details'!$A:$H, 7, FALSE) -> 47496.49 | M20: =VLOOKUP($A20, 'Hospitalisation Details'!$A:$L, 12, FALSE) -> tier - 1 | N20: =VLOOKUP($A20, 'Hospitalisation Details'!$A:$M, 13, FALSE) -> tier - 3 | O20: =VLOOKUP($A20, 'Hospitalisation Details'!$A:$N, 14, FALSE) -> R1012 | P20: =VLOOKUP($A20, 'Hospitalisation Details'!$A:$O, 15, FALSE) -> 58
... A2334: Id2333 | B2334: =VLOOKUP($A2334,'Customer Names'!$A:$D,3, FALSE) -> Albano | C2334: =VLOOKUP($A2334,'Medical Examinations'!$A:$D, 2, FALSE) -> 16.47 | D2334: =VLOOKUP($A2334, 'Medical Examinations'!$A:$D,3, FALSE) -> 6.35 | E2334: =VLOOKUP($A2334, 'Medical Examinations'!$A:$D, 4, FALSE) -> No | F2334: =VLOOKUP($A2334, 'Medical Examinations'!$A:$J, 5, FALSE) -> No | G2334: =VLOOKUP($A2334, 'Medical Examinations'!$A:$I, 6, FALSE) -> Yes | H2334: =VLOOKUP($A2334,'Medical Examinations'!$A:$L,10, FALSE) -> 1 | I2334: =VLOOKUP($A2334, 'Medical Examinations'!$A:$J, 9, FALSE) -> No | J2334: =VLOOKUP($A2334, 'Medical Examinations'!$A:$P, 11, FALSE) -> UNDERWEIGHT | K2334: 22893 | L2334: =VLOOKUP($A2334, 'Hospitalisation Details'!$A:$H, 7, FALSE) -> 600 | M2334: =VLOOKUP($A2334, 'Hospitalisation Details'!$A:$L, 12, FALSE) -> tier - 2 | N2334: =VLOOKUP($A2334, 'Hospitalisation Details'!$A:$M, 13, FALSE) -> tier - 1 | O2334: =VLOOKUP($A2334, 'Hospitalisation Details'!$A:$N, 14, FALSE) -> R1013 | P2334: =VLOOKUP($A2334, 'Hospitalisation Details'!$A:$O, 15, FALSE) -> 29
A2335: Id2334 | B2335: =VLOOKUP($A2335,'Customer Names'!$A:$D,3, FALSE) -> Rosendahl | C2335: =VLOOKUP($A2335,'Medical Examinations'!$A:$D, 2, FALSE) -> 17.6 | D2335: =VLOOKUP($A2335, 'Medical Examinations'!$A:$D,3, FALSE) -> 4.39 | E2335: =VLOOKUP($A2335, 'Medical Examinations'!$A:$D, 4, FALSE) -> No | F2335: =VLOOKUP($A2335, 'Medical Examinations'!$A:$J, 5, FALSE) -> No | G2335: =VLOOKUP($A2335, 'Medical Examinations'!$A:$I, 6, FALSE) -> No | H2335: =VLOOKUP($A2335,'Medical Examinations'!$A:$L,10, FALSE) -> 1 | I2335: =VLOOKUP($A2335, 'Medical Examinations'!$A:$J, 9, FALSE) -> No | J2335: =VLOOKUP($A2335, 'Medical Examinations'!$A:$P, 11, FALSE) -> UNDERWEIGHT | K2335: 25117 | L2335: =VLOOKUP($A2335, 'Hospitalisation Details'!$A:$H, 7, FALSE) -> 570.62 | M2335: =VLOOKUP($A2335, 'Hospitalisation Details'!$A:$L, 12, FALSE) -> tier - 2 | N2335: =VLOOKUP($A2335, 'Hospitalisation Details'!$A:$M, 13, FALSE) -> tier - 1 | O2335: =VLOOKUP($A2335, '[3]Hospitalisation Details'!$A:$N, 14, FALSE) -> #REF! | P2335: =VLOOKUP($A2335, 'Hospitalisation Details'!$A:$O, 15, FALSE) -> 30

Sheet Dashboard
F1: Healthcare Dashboard

Sheet Insight Summary
A4: Insight summary
A6: Cancer History Distribution – Insights 1. A higher percentage of smokers had a history of cancer compared to non-smokers. 2. Non-smokers show a lower cancer incidence, indicating a possible risk reduction. 3. If the smoker group is significantly larger, the chart highlights the impact of smoking on cancer history. 4. The pie chart clearly shows the proportion difference between smoker and non-smoker categories. 5. This insight supports the correlation between smoking behavior and cancer probability. | B6: Findings • Smokers show significantly higher cancer cases. • Possible correlation between smoking and cancer risk.
A7: Charges by Weight Status – Insights 1. The 'Obese' weight group shows the highest average hospital charges. 2. Normal and overweight groups have moderate billing amounts. 3. Underweight patients have comparatively lower treatment charges. 4. The graph indicates that healthcare costs increase with weight category. 5. This suggests higher medical complexity or increased interventions for obese patients. | B7: • Highest charges: Obese group (₹16,591 average) • Lowest charges: Underweight (₹ 6,899average) • Charges rise as BMI category increases. • Indicates increased treatment complexity.
